Workbook

Sheet Annahmen
A1: Deckungsbeitragsrechnung – Annahmen & Parameter
A2: Parameter | B2: Einheit | C2: 2025 | D2: 2026 | E2: 2027 | F2: 2028 | G2: 2029
A3: 1. Umsatzwachstum p.a.
A4: Produktverkauf | B4: % | C4: 0 | D4: 0.05 | E4: 0.05 | F4: 0.05 | G4: 0.05
A5: Serviceleistungen | B5: % | C5: 0 | D5: 0.05 | E5: 0.05 | F5: 0.05 | G5: 0.05
A6: Lizenzeinnahmen | B6: % | C6: 0 | D6: 0.05 | E6: 0.05 | F6: 0.05 | G6: 0.05
A7: Sonstiger Umsatz | B7: % | C7: 0 | D7: 0.05 | E7: 0.05 | F7: 0.05 | G7: 0.05
A9: 2. Basisumsatz 2025 (€)
A10: Produktverkauf | B10: € | C10: 500000
A11: Serviceleistungen | B11: € | C11: 200000
A12: Lizenzeinnahmen | B12: € | C12: 100000
A13: Sonstiger Umsatz | B13: € | C13: 50000
A15: 3. Materialkostenquote (% vom Umsatz)
A16: Produktverkauf | B16: % | C16: 0.35 | D16: 0.35 | E16: 0.35 | F16: 0.35 | G16: 0.35
A17: Serviceleistungen | B17: % | C17: 0.15 | D17: 0.15 | E17: 0.15 | F17: 0.15 | G17: 0.15
A18: Lizenzeinnahmen | B18: % | C18: 0.05 | D18: 0.05 | E18: 0.05 | F18: 0.05 | G18: 0.05
A19: Sonstiger Umsatz | B19: % | C19: 0.3 | D19: 0.3 | E19: 0.3 | F19: 0.3 | G19: 0.3
A21: 4. Direkte Personalkosten (€ p.a.)
A22: Produktverkauf | B22: € | C22: 120000 | D22: 120000 | E22: 120000 | F22: 120000 | G22: 120000
A23: Serviceleistungen | B23: € | C23: 60000 | D23: 60000 | E23: 60000 | F23: 60000 | G23: 60000
A24: Lizenzeinnahmen | B24: € | C24: 20000 | D24: 20000 | E24: 20000 | F24: 20000 | G24: 20000
A25: Sonstiger Umsatz | B25: € | C25: 15000 | D25: 15000 | E25: 15000 | F25: 15000 | G25: 15000
A27: 5. Direkte sonstige Kosten (€ p.a.)
A28: Produktverkauf | B28: € | C28: 30000 | D28: 30000 | E28: 30000 | F28: 30000 | G28: 30000
A29: Serviceleistungen | B29: € | C29: 15000 | D29: 15000 | E29: 15000 | F29: 15000 | G29: 15000
A30: Lizenzeinnahmen | B30: € | C30: 8000 | D30: 8000 | E30: 8000 | F30: 8000 | G30: 8000
A31: Sonstiger Umsatz | B31: € | C31: 5000 | D31: 5000 | E31: 5000 | F31: 5000 | G31: 5000
A33: 6. Overhead DB2 – PersonalEx (€ p.a.)
A34: Verwaltung PerEx | B34: € | C34: 80000 | D34: 82000 | E34: 84000 | F34: 86000 | G34: 88000
A35: Entwicklung PerEx | B35: € | C35: 50000 | D35: 51250 | E35: 52500 | F35: 53750 | G35: 55000
A36: Vertrieb PerEx | B36: € | C36: 70000 | D36: 71750 | E36: 73500 | F36: 75250 | G36: 77000
A37: Overhead DB2 PerEx Gesamt | B37: € | C37: =SUM(C34:C36) | D37: =SUM(D34:D36) | E37: =SUM(E34:E36) | F37: =SUM(F34:F36) | G37: =SUM(G34:G36)
A38: 7. Overhead DB2 – OpEx (€ p.a.)
A39: Verwaltung OpEx | B39: € | C39: 32000 | D39: 32800 | E39: 33600 | F39: 34400 | G39: 35200
A40: Entwicklung OpEx | B40: € | C40: 20000 | D40: 20500 | E40: 21000 | F40: 21500 | G40: 22000
A41: Vertrieb OpEx | B41: € | C41: 28000 | D41: 28700 | E41: 29400 | F41: 30100 | G41: 30800
A42: Overhead DB2 OpEx Gesamt | B42: € | C42: =SUM(C39:C41) | D42: =SUM(D39:D41) | E42: =SUM(E39:E41) | F42: =SUM(F39:F41) | G42: =SUM(G39:G41)
A44: 8. Overhead DB3 – PersonalEx (€ p.a.)
A45: Overhead DB3 PerEx Gesamt | B45: € | C45: 150000 | D45: 154000 | E45: 158000 | F45: 162000 | G45: 166000
A46: 9. Overhead DB3 – OpEx (€ p.a.)
...

Sheet Gesamt P&L
A1: Mehrstufige Deckungsbeitragsrechnung – 5-Jahres-Simulation
A2: Position | C2: 2025 | D2: 2026 | E2: 2027 | F2: 2028 | G2: 2029 | H2: Ø Marge
A4: UMSATZ
A5: Produktverkauf | C5: =Annahmen!C10 | D5: =Annahmen!C10*(1+Annahmen!D4) | E5: =Annahmen!C10*(1+Annahmen!D4)*(1+Annahmen!E4) | F5: =Annahmen!C10*(1+Annahmen!D4)*(1+Annahmen!E4)*(1+Annahmen!F4) | G5: =Annahmen!C10*(1+Annahmen!D4)*(1+Annahmen!E4)*(1+Annahmen!F4)*(1+Annahmen!G4)
A6: Serviceleistungen | C6: =Annahmen!C11 | D6: =Annahmen!C11*(1+Annahmen!D5) | E6: =Annahmen!C11*(1+Annahmen!D5)*(1+Annahmen!E5) | F6: =Annahmen!C11*(1+Annahmen!D5)*(1+Annahmen!E5)*(1+Annahmen!F5) | G6: =Annahmen!C11*(1+Annahmen!D5)*(1+Annahmen!E5)*(1+Annahmen!F5)*(1+Annahmen!G5)
A7: Lizenzeinnahmen | C7: =Annahmen!C12 | D7: =Annahmen!C12*(1+Annahmen!D6) | E7: =Annahmen!C12*(1+Annahmen!D6)*(1+Annahmen!E6) | F7: =Annahmen!C12*(1+Annahmen!D6)*(1+Annahmen!E6)*(1+Annahmen!F6) | G7: =Annahmen!C12*(1+Annahmen!D6)*(1+Annahmen!E6)*(1+Annahmen!F6)*(1+Annahmen!G6)
A8: Sonstiger Umsatz | C8: =Annahmen!C13 | D8: =Annahmen!C13*(1+Annahmen!D7) | E8: =Annahmen!C13*(1+Annahmen!D7)*(1+Annahmen!E7) | F8: =Annahmen!C13*(1+Annahmen!D7)*(1+Annahmen!E7)*(1+Annahmen!F7) | G8: =Annahmen!C13*(1+Annahmen!D7)*(1+Annahmen!E7)*(1+Annahmen!F7)*(1+Annahmen!G7)
A9: Gesamtumsatz | C9: =C5+C6+C7+C8 | D9: =D5+D6+D7+D8 | E9: =E5+E6+E7+E8 | F9: =F5+F6+F7+F8 | G9: =G5+G6+G7+G8 | H9: 100%
A11: DIREKTE MATERIALKOSTEN
A12: Produktverkauf | C12: =-C5*Annahmen!C16 | D12: =-D5*Annahmen!D16 | E12: =-E5*Annahmen!E16 | F12: =-F5*Annahmen!F16 | G12: =-G5*Annahmen!G16
A13: Serviceleistungen | C13: =-C6*Annahmen!C17 | D13: =-D6*Annahmen!D17 | E13: =-E6*Annahmen!E17 | F13: =-F6*Annahmen!F17 | G13: =-G6*Annahmen!G17
A14: Lizenzeinnahmen | C14: =-C7*Annahmen!C18 | D14: =-D7*Annahmen!D18 | E14: =-E7*Annahmen!E18 | F14: =-F7*Annahmen!F18 | G14: =-G7*Annahmen!G18
A15: Sonstiger Umsatz | C15: =-C8*Annahmen!C19 | D15: =-D8*Annahmen!D19 | E15: =-E8*Annahmen!E19 | F15: =-F8*Annahmen!F19 | G15: =-G8*Annahmen!G19
A16: Gesamt Materialkosten | C16: =C12+C13+C14+C15 | D16: =D12+D13+D14+D15 | E16: =E12+E13+E14+E15 | F16: =F12+F13+F14+F15 | G16: =G12+G13+G14+G15 | H16: =IF(G9<>0,G16/G9,0)
A18: GROSS PROFIT | C18: =C9+C16 | D18: =D9+D16 | E18: =E9+E16 | F18: =F9+F16 | G18: =G9+G16 | H18: =IF(G9<>0,G18/G9,0)
A20: DIREKTE PERSONALKOSTEN
A21: Produktverkauf | C21: =-Annahmen!C22 | D21: =-Annahmen!D22 | E21: =-Annahmen!E22 | F21: =-Annahmen!F22 | G21: =-Annahmen!G22
A22: Serviceleistungen | C22: =-Annahmen!C23 | D22: =-Annahmen!D23 | E22: =-Annahmen!E23 | F22: =-Annahmen!F23 | G22: =-Annahmen!G23
A23: Lizenzeinnahmen | C23: =-Annahmen!C24 | D23: =-Annahmen!D24 | E23: =-Annahmen!E24 | F23: =-Annahmen!F24 | G23: =-Annahmen!G24
A24: Sonstiger Umsatz | C24: =-Annahmen!C25 | D24: =-Annahmen!D25 | E24: =-Annahmen!E25 | F24: =-Annahmen!F25 | G24: =-Annahmen!G25
A25: Gesamt direkte Personalkosten | C25: =C21+C22+C23+C24 | D25: =D21+D22+D23+D24 | E25: =E21+E22+E23+E24 | F25: =F21+F22+F23+F24 | G25: =G21+G22+G23+G24
A27: DIREKTE SONSTIGE KOSTEN
A28: Produktverkauf | C28: =-Annahmen!C28 | D28: =-Annahmen!D28 | E28: =-Annahmen!E28 | F28: =-Annahmen!F28 | G28: =-Annahmen!G28
A29: Serviceleistungen | C29: =-Annahmen!C29 | D29: =-Annahmen!D29 | E29: =-Annahmen!E29 | F29: =-Annahmen!F29 | G29: =-Annahmen!G29
A30: Lizenzeinnahmen | C30: =-Annahmen!C30 | D30: =-Annahmen!D30 | E30: =-Annahmen!E30 | F30: =-Annahmen!F30 | G30: =-Annahmen!G30
A31: Sonstiger Umsatz | C31: =-Annahmen!C31 | D31: =-Annahmen!D31 | E31: =-Annahmen!E31 | F31: =-Annahmen!F31 | G31: =-Annahmen!G31
A32: Gesamt direkte sonstige Kosten | C32: =C28+C29+C30+C31 | D32: =D28+D29+D30+D31 | E32: =E28+E29+E30+E31 | F32: =F28+F29+F30+F31 | G32: =G28+G29+G30+G31
A34: DECKUNGSBEITRAG 1 (DB1) | C34: =C18+C25+C32 | D34: =D18+D25+D32 | E34: =E18+E25+E32 | F34: =F18+F25+F32 | G34: =G18+G25+G32 | H34: =IF(G9<>0,G34/G9,0)
A36: OVERHEAD DB2
A37: Verwaltung – PersonalEx | C37: =-Annahmen!C34 | D37: =-Annahmen!D34 | E37: =-Annahmen!E34 | F37: =-Annahmen!F34 | G37: =-Annahmen!G34
A38: Entwicklung – PersonalEx | C38: =-Annahmen!C35 | D38: =-Annahmen!D35 | E38: =-Annahmen!E35 | F38: =-Annahmen!F35 | G38: =-Annahmen!G35
A39: Vertrieb – PersonalEx | C39: =-Annahmen!C36 | D39: =-Annahmen!D36 | E39: =-Annahmen!E36 | F39: =-Annahmen!F36 | G39: =-Annahmen!G36
A40: Overhead DB2 – PersonalEx Gesamt | C40: =SUM(C37:C39) | D40: =SUM(D37:D39) | E40: =SUM(E37:E39) | F40: =SUM(F37:F39) | G40: =SUM(G37:G39)
A41: Verwaltung – OpEx | C41: =-Annahmen!C39 | D41: =-Annahmen!D39 | E41: =-Annahmen!E39 | F41: =-Annahmen!F39 | G41: =-Annahmen!G39
A42: Entwicklung – OpEx | C42: =-Annahmen!C40 | D42: =-Annahmen!D40 | E42: =-Annahmen!E40 | F42: =-Annahmen!F40 | G42: =-Annahmen!G40
A43: Vertrieb – OpEx | C43: =-Annahmen!C41 | D43: =-Annahmen!D41 | E43: =-Annahmen!E41 | F43: =-Annahmen!F41 | G43: =-Annahmen!G41
A44: Overhead DB2 – OpEx Gesamt | C44: =SUM(C41:C43) | D44: =SUM(D41:D43) | E44: =SUM(E41:E43) | F44: =SUM(F41:F43) | G44: =SUM(G41:G43)
A46: DECKUNGSBEITRAG 2 (DB2) | C46: =C34+C40+C44 | D46: =D34+D40+D44 | E46: =E34+E40+E44 | F46: =F34+F40+F44 | G46: =G34+G40+G44 | H46: =IF(G9<>0,G46/G9,0)
A48: OVERHEAD DB3
A49: Overhead DB3 – PersonalEx | C49: =-Annahmen!C45 | D49: =-Annahmen!D45 | E49: =-Annahmen!E45 | F49: =-Annahmen!F45 | G49: =-Annahmen!G45
...

Sheet Kennzahlen
A1: Kennzahlen-Dashboard – Margen & Wachstum
A2: Kennzahl | C2: 2025 | D2: 2026 | E2: 2027 | F2: 2028 | G2: 2029
A3: Gesamtumsatz | C3: ='Gesamt P&L'!C9 | D3: ='Gesamt P&L'!D9 | E3: ='Gesamt P&L'!E9 | F3: ='Gesamt P&L'!F9 | G3: ='Gesamt P&L'!G9
A4: Gross Profit | C4: ='Gesamt P&L'!C18 | D4: ='Gesamt P&L'!D18 | E4: ='Gesamt P&L'!E18 | F4: ='Gesamt P&L'!F18 | G4: ='Gesamt P&L'!G18
A5: Gross Margin % | C5: =IF('Gesamt P&L'!C9<>0,'Gesamt P&L'!C18/'Gesamt P&L'!C9,0) | D5: =IF('Gesamt P&L'!D9<>0,'Gesamt P&L'!D18/'Gesamt P&L'!D9,0) | E5: =IF('Gesamt P&L'!E9<>0,'Gesamt P&L'!E18/'Gesamt P&L'!E9,0) | F5: =IF('Gesamt P&L'!F9<>0,'Gesamt P&L'!F18/'Gesamt P&L'!F9,0) | G5: =IF('Gesamt P&L'!G9<>0,'Gesamt P&L'!G18/'Gesamt P&L'!G9,0)
A6: Deckungsbeitrag 1 | C6: ='Gesamt P&L'!C34 | D6: ='Gesamt P&L'!D34 | E6: ='Gesamt P&L'!E34 | F6: ='Gesamt P&L'!F34 | G6: ='Gesamt P&L'!G34
A7: DB1-Marge % | C7: =IF('Gesamt P&L'!C9<>0,'Gesamt P&L'!C34/'Gesamt P&L'!C9,0) | D7: =IF('Gesamt P&L'!D9<>0,'Gesamt P&L'!D34/'Gesamt P&L'!D9,0) | E7: =IF('Gesamt P&L'!E9<>0,'Gesamt P&L'!E34/'Gesamt P&L'!E9,0) | F7: =IF('Gesamt P&L'!F9<>0,'Gesamt P&L'!F34/'Gesamt P&L'!F9,0) | G7: =IF('Gesamt P&L'!G9<>0,'Gesamt P&L'!G34/'Gesamt P&L'!G9,0)
A8: Deckungsbeitrag 2 | C8: ='Gesamt P&L'!C46 | D8: ='Gesamt P&L'!D46 | E8: ='Gesamt P&L'!E46 | F8: ='Gesamt P&L'!F46 | G8: ='Gesamt P&L'!G46
A9: DB2-Marge % | C9: =IF('Gesamt P&L'!C9<>0,'Gesamt P&L'!C46/'Gesamt P&L'!C9,0) | D9: =IF('Gesamt P&L'!D9<>0,'Gesamt P&L'!D46/'Gesamt P&L'!D9,0) | E9: =IF('Gesamt P&L'!E9<>0,'Gesamt P&L'!E46/'Gesamt P&L'!E9,0) | F9: =IF('Gesamt P&L'!F9<>0,'Gesamt P&L'!F46/'Gesamt P&L'!F9,0) | G9: =IF('Gesamt P&L'!G9<>0,'Gesamt P&L'!G46/'Gesamt P&L'!G9,0)
A10: Deckungsbeitrag 3 | C10: ='Gesamt P&L'!C52 | D10: ='Gesamt P&L'!D52 | E10: ='Gesamt P&L'!E52 | F10: ='Gesamt P&L'!F52 | G10: ='Gesamt P&L'!G52
A11: DB3-Marge % | C11: =IF('Gesamt P&L'!C9<>0,'Gesamt P&L'!C52/'Gesamt P&L'!C9,0) | D11: =IF('Gesamt P&L'!D9<>0,'Gesamt P&L'!D52/'Gesamt P&L'!D9,0) | E11: =IF('Gesamt P&L'!E9<>0,'Gesamt P&L'!E52/'Gesamt P&L'!E9,0) | F11: =IF('Gesamt P&L'!F9<>0,'Gesamt P&L'!F52/'Gesamt P&L'!F9,0) | G11: =IF('Gesamt P&L'!G9<>0,'Gesamt P&L'!G52/'Gesamt P&L'!G9,0)
A13: Umsatzwachstum YoY
A14: Wachstum Gesamtumsatz % | C14: — | D14: =IF('Gesamt P&L'!C9<>0,('Gesamt P&L'!D9-'Gesamt P&L'!C9)/'Gesamt P&L'!C9,0) | E14: =IF('Gesamt P&L'!D9<>0,('Gesamt P&L'!E9-'Gesamt P&L'!D9)/'Gesamt P&L'!D9,0) | F14: =IF('Gesamt P&L'!E9<>0,('Gesamt P&L'!F9-'Gesamt P&L'!E9)/'Gesamt P&L'!E9,0) | G14: =IF('Gesamt P&L'!F9<>0,('Gesamt P&L'!G9-'Gesamt P&L'!F9)/'Gesamt P&L'!F9,0)

Sheet BreakEven
A1: Break-Even-Simulation (DB3=0)
A2: Annahmen: Bruttomarge konstant, Materialkosten proportional, direkte Kosten & Overheads wie Modell (fix/plan).
A4: Jahr | B4: Ist_Gesamtumsatz | C4: Bruttomarge | D4: Fixe_Direktkosten | E4: Overhead_DB2 | F4: Overhead_DB3 | G4: BreakEven_Umsatz | H4: Zusatzumsatz_vs_Ist | I4: Multiplikator_vs_Ist
A5: 2025 | B5: 850000 | C5: 0.73529412 | D5: 273000 | E5: 280000 | F5: 200000 | G5: 1024080 | H5: 174080 | I5: 1.2048
A6: 2026 | B6: 892500 | C6: 0.73529412 | D6: 273000 | E6: 287000 | F6: 205500 | G6: 1041080 | H6: 148580 | I6: 1.1664762
A7: 2027 | B7: 937125 | C7: 0.73529412 | D7: 273000 | E7: 294000 | F7: 211000 | G7: 1058080 | H7: 120955 | I7: 1.1290703
A8: 2028 | B8: 983981.25 | C8: 0.73529412 | D8: 273000 | E8: 301000 | F8: 216500 | G8: 1075080 | H8: 91098.75 | I8: 1.0925818
A9: 2029 | B9: 1033180.3 | C9: 0.73529412 | D9: 273000 | E9: 308000 | F9: 222000 | G9: 1092080 | H9: 58899.688 | I9: 1.0570081
A12: Break-even 2029 erfordert Umsatz (ab 2025) CAGR: | B12: 0.064654961
A13: Break-even Umsatz 2029: | B13: 1092080
A16: Sensitivität 2029: DB3 (in €) bei Umsatz-Multiplikator vs. Reduktion Overhead DB3
B17: 90% Umsatz | C17: 95% Umsatz | D17: 100% Umsatz | E17: 105% Umsatz | F17: 110% Umsatz | G17: 114% Umsatz | H17: 120% Umsatz | I17: 125% Umsatz | J17: 130% Umsatz | K17: 135% Umsatz | L17: 140% Umsatz
A18: -0% OH3 | B18: -119277.73 | C18: -81293.164 | D18: -43308.594 | E18: -5324.0234 | F18: 32660.547 | G18: 70645.117 | H18: 108629.69 | I18: 146614.26 | J18: 184598.83 | K18: 222583.4 | L18: 260567.97
A19: -5% OH3 | B19: -108177.73 | C19: -70193.164 | D19: -32208.594 | E19: 5775.9766 | F19: 43760.547 | G19: 81745.117 | H19: 119729.69 | I19: 157714.26 | J19: 195698.83 | K19: 233683.4 | L19: 271667.97
A20: -10% OH3 | B20: -97077.734 | C20: -59093.164 | D20: -21108.594 | E20: 16875.977 | F20: 54860.547 | G20: 92845.117 | H20: 130829.69 | I20: 168814.26 | J20: 206798.83 | K20: 244783.4 | L20: 282767.97
A21: -15% OH3 | B21: -85977.734 | C21: -47993.164 | D21: -10008.594 | E21: 27975.977 | F21: 65960.547 | G21: 103945.12 | H21: 141929.69 | I21: 179914.26 | J21: 217898.83 | K21: 255883.4 | L21: 293867.97
A22: -20% OH3 | B22: -74877.734 | C22: -36893.164 | D22: 1091.4062 | E22: 39075.977 | F22: 77060.547 | G22: 115045.12 | H22: 153029.69 | I22: 191014.26 | J22: 228998.83 | K22: 266983.4 | L22: 304967.97
A23: -25% OH3 | B23: -63777.734 | C23: -25793.164 | D23: 12191.406 | E23: 50175.977 | F23: 88160.547 | G23: 126145.12 | H23: 164129.69 | I23: 202114.26 | J23: 240098.83 | K23: 278083.4 | L23: 316067.97
A24: -30% OH3 | B24: -52677.734 | C24: -14693.164 | D24: 23291.406 | E24: 61275.977 | F24: 99260.547 | G24: 137245.12 | H24: 175229.69 | I24: 213214.26 | J24: 251198.83 | K24: 289183.4 | L24: 327167.97
A25: -35% OH3 | B25: -41577.734 | C25: -3593.1641 | D25: 34391.406 | E25: 72375.977 | F25: 110360.55 | G25: 148345.12 | H25: 186329.69 | I25: 224314.26 | J25: 262298.83 | K25: 300283.4 | L25: 338267.97
A26: -40% OH3 | B26: -30477.734 | C26: 7506.8359 | D26: 45491.406 | E26: 83475.977 | F26: 121460.55 | G26: 159445.12 | H26: 197429.69 | I26: 235414.26 | J26: 273398.83 | K26: 311383.4 | L26: 349367.97
